src.exception.CustomException
src.exception.CustomException: Error occurred python script name [/home/runner/workspace/app.py] line number [20] error message [Error occurred python script name [/home/runner/workspace/src/pipeline/train_pipeline.py] line number [53] error message [Error occurred python script name [/home/runner/workspace/src/pipeline/train_pipeline.py] line number [19] error message [Error occurred python script name [/home/runner/workspace/src/components/data_ingestion.py] line number [95] error message [Error occurred python script name [/home/runner/workspace/src/components/data_ingestion.py] line number [63] error message [Error occurred python script name [/home/runner/workspace/src/components/data_ingestion.py] line number [34] error message [SSL handshake failed: ac-turoufc-shard-00-00.omqemyy.mongodb.net:27017: [SSL: TLSV1_ALERT_INTERNAL_ERROR] tlsv1 alert internal error (_ssl.c:1131),SSL handshake failed: ac-turoufc-shard-00-02.omqemyy.mongodb.net:27017: [SSL: TLSV1_ALERT_INTERNAL_ERROR] tlsv1 alert internal error (_ssl.c:1131),SSL handshake failed: ac-turoufc-shard-00-01.omqemyy.mongodb.net:27017: [SSL: TLSV1_ALERT_INTERNAL_ERROR] tlsv1 alert internal error (_ssl.c:1131), Timeout: 30s, Topology Description: <TopologyDescription id: 682399706def02f992bea2ec, topology_type: ReplicaSetNoPrimary, servers: [<ServerDescription ('ac-turoufc-shard-00-00.omqemyy.mongodb.net', 27017) server_type: Unknown, rtt: None, error=AutoReconnect('SSL handshake failed: ac-turoufc-shard-00-00.omqemyy.mongodb.net:27017: [SSL: TLSV1_ALERT_INTERNAL_ERROR] tlsv1 alert internal error (_ssl.c:1131)')>, <ServerDescription ('ac-turoufc-shard-00-01.omqemyy.mongodb.net', 27017) server_type: Unknown, rtt: None, error=AutoReconnect('SSL handshake failed: ac-turoufc-shard-00-01.omqemyy.mongodb.net:27017: [SSL: TLSV1_ALERT_INTERNAL_ERROR] tlsv1 alert internal error (_ssl.c:1131)')>, <ServerDescription ('ac-turoufc-shard-00-02.omqemyy.mongodb.net', 27017) server_type: Unknown, rtt: None, error=AutoReconnect('SSL handshake failed: ac-turoufc-shard-00-02.omqemyy.mongodb.net:27017: [SSL: TLSV1_ALERT_INTERNAL_ERROR] tlsv1 alert internal error (_ssl.c:1131)')>]>]]]]]]

Traceback (most recent call last)
File "/home/runner/workspace/src/components/data_ingestion.py", line 34, in export_collection_as_dataframe
df = pd.DataFrame(list(collection.find()))
File "/home/runner/workspace/.pythonlibs/lib/python3.8/site-packages/pymongo/cursor.py", line 1248, in next
if len(self.__data) or self._refresh():
File "/home/runner/workspace/.pythonlibs/lib/python3.8/site-packages/pymongo/cursor.py", line 1139, in _refresh
self.__session = self.__collection.database.client._ensure_session()
File "/home/runner/workspace/.pythonlibs/lib/python3.8/site-packages/pymongo/mongo_client.py", line 1712, in _ensure_session
return self.__start_session(True, causal_consistency=False)
File "/home/runner/workspace/.pythonlibs/lib/python3.8/site-packages/pymongo/mongo_client.py", line 1657, in __start_session
self._topology._check_implicit_session_support()
File "/home/runner/workspace/.pythonlibs/lib/python3.8/site-packages/pymongo/topology.py", line 538, in _check_implicit_session_support
self._check_session_support()
File "/home/runner/workspace/.pythonlibs/lib/python3.8/site-packages/pymongo/topology.py", line 554, in _check_session_support
self._select_servers_loop(
File "/home/runner/workspace/.pythonlibs/lib/python3.8/site-packages/pymongo/topology.py", line 238, in _select_servers_loop
raise ServerSelectionTimeoutError(
During handling of the above exception, another exception occurred:
File "/home/runner/workspace/src/components/data_ingestion.py", line 63, in export_data_into_feature_store_file_path
sensor_data = self.export_collection_as_dataframe(
File "/home/runner/workspace/src/components/data_ingestion.py", line 44, in export_collection_as_dataframe
raise CustomException(e, sys)
During handling of the above exception, another exception occurred:
File "/home/runner/workspace/src/components/data_ingestion.py", line 95, in initiate_data_ingestion
feature_store_file_path = self.export_data_into_feature_store_file_path()
File "/home/runner/workspace/src/components/data_ingestion.py", line 78, in export_data_into_feature_store_file_path
raise CustomException(e,sys)
The above exception was the direct cause of the following exception:
File "/home/runner/workspace/src/pipeline/train_pipeline.py", line 19, in start_data_ingestion
feature_store_file_path = data_ingestion.initiate_data_ingestion()
File "/home/runner/workspace/src/components/data_ingestion.py", line 107, in initiate_data_ingestion
raise CustomException(e, sys) from e
During handling of the above exception, another exception occurred:
File "/home/runner/workspace/src/pipeline/train_pipeline.py", line 53, in run_pipeline
feature_store_file_path = self.start_data_ingestion()
File "/home/runner/workspace/src/pipeline/train_pipeline.py", line 23, in start_data_ingestion
raise CustomException(e,sys)
During handling of the above exception, another exception occurred:
File "/home/runner/workspace/app.py", line 20, in train_route
train_pipeline.run_pipeline()
File "/home/runner/workspace/src/pipeline/train_pipeline.py", line 61, in run_pipeline
raise CustomException(e, sys)
During handling of the above exception, another exception occurred:
File "/home/runner/workspace/.pythonlibs/lib/python3.8/site-packages/flask/app.py", line 2088, in __call__
return self.wsgi_app(environ, start_response)
File "/home/runner/workspace/.pythonlibs/lib/python3.8/site-packages/flask/app.py", line 2073, in wsgi_app
response = self.handle_exception(e)
File "/home/runner/workspace/.pythonlibs/lib/python3.8/site-packages/flask/app.py", line 2070, in wsgi_app
response = self.full_dispatch_request()
File "/home/runner/workspace/.pythonlibs/lib/python3.8/site-packages/flask/app.py", line 1515, in full_dispatch_request
rv = self.handle_user_exception(e)
File "/home/runner/workspace/.pythonlibs/lib/python3.8/site-packages/flask/app.py", line 1513, in full_dispatch_request
rv = self.dispatch_request()
File "/home/runner/workspace/.pythonlibs/lib/python3.8/site-packages/flask/app.py", line 1499, in dispatch_request
return self.ensure_sync(self.view_functions[rule.endpoint])(**req.view_args)
File "/home/runner/workspace/app.py", line 23, in train_route
raise CustomException(e, sys)
src.exception.CustomException: Error occurred python script name [/home/runner/workspace/app.py] line number [20] error message [Error occurred python script name [/home/runner/workspace/src/pipeline/train_pipeline.py] line number [53] error message [Error occurred python script name [/home/runner/workspace/src/pipeline/train_pipeline.py] line number [19] error message [Error occurred python script name [/home/runner/workspace/src/components/data_ingestion.py] line number [95] error message [Error occurred python script name [/home/runner/workspace/src/components/data_ingestion.py] line number [63] error message [Error occurred python script name [/home/runner/workspace/src/components/data_ingestion.py] line number [34] error message [SSL handshake failed: ac-turoufc-shard-00-00.omqemyy.mongodb.net:27017: [SSL: TLSV1_ALERT_INTERNAL_ERROR] tlsv1 alert internal error (_ssl.c:1131),SSL handshake failed: ac-turoufc-shard-00-02.omqemyy.mongodb.net:27017: [SSL: TLSV1_ALERT_INTERNAL_ERROR] tlsv1 alert internal error (_ssl.c:1131),SSL handshake failed: ac-turoufc-shard-00-01.omqemyy.mongodb.net:27017: [SSL: TLSV1_ALERT_INTERNAL_ERROR] tlsv1 alert internal error (_ssl.c:1131), Timeout: 30s, Topology Description: <TopologyDescription id: 682399706def02f992bea2ec, topology_type: ReplicaSetNoPrimary, servers: [<ServerDescription ('ac-turoufc-shard-00-00.omqemyy.mongodb.net', 27017) server_type: Unknown, rtt: None, error=AutoReconnect('SSL handshake failed: ac-turoufc-shard-00-00.omqemyy.mongodb.net:27017: [SSL: TLSV1_ALERT_INTERNAL_ERROR] tlsv1 alert internal error (_ssl.c:1131)')>, <ServerDescription ('ac-turoufc-shard-00-01.omqemyy.mongodb.net', 27017) server_type: Unknown, rtt: None, error=AutoReconnect('SSL handshake failed: ac-turoufc-shard-00-01.omqemyy.mongodb.net:27017: [SSL: TLSV1_ALERT_INTERNAL_ERROR] tlsv1 alert internal error (_ssl.c:1131)')>, <ServerDescription ('ac-turoufc-shard-00-02.omqemyy.mongodb.net', 27017) server_type: Unknown, rtt: None, error=AutoReconnect('SSL handshake failed: ac-turoufc-shard-00-02.omqemyy.mongodb.net:27017: [SSL: TLSV1_ALERT_INTERNAL_ERROR] tlsv1 alert internal error (_ssl.c:1131)')>]>]]]]]]